 * Serving Flask app 'main'
 * Debug mode: off
WARNING: This is a development server. Do not use it in a production deployment. Use a production WSGI server instead.
 * Running on all addresses (0.0.0.0)
 * Running on http://127.0.0.1:3000
 * Running on http://172.31.196.69:3000
Press CTRL+C to quit
172.31.196.69 - - [04/Jan/2025 23:19:05] "GET / HTTP/1.1" 200 -
ERROR:main:Exception on / [POST]
Traceback (most recent call last):
  File "/home/runner/hypercover/.pythonlibs/lib/python3.13/site-packages/flask/app.py", line 1511, in wsgi_app
    response = self.full_dispatch_request()
  File "/home/runner/hypercover/.pythonlibs/lib/python3.13/site-packages/flask/app.py", line 919, in full_dispatch_request
    rv = self.handle_user_exception(e)
  File "/home/runner/hypercover/.pythonlibs/lib/python3.13/site-packages/flask/app.py", line 917, in full_dispatch_request
    rv = self.dispatch_request()
  File "/home/runner/hypercover/.pythonlibs/lib/python3.13/site-packages/flask/app.py", line 902, in dispatch_request
    return self.ensure_sync(self.view_functions[rule.endpoint])(**view_args)  # type: ignore[no-any-return]
           ~~~~~~~~~~~~~~~~~~~~~~~~~~~~~~~~~~~~~~~~~~~~~~~~~~~~^^^^^^^^^^^^^
  File "/home/runner/hypercover/main.py", line 18, in index
    company_info = companyfinder.getCompany(company)
  File "/home/runner/hypercover/companyfinder.py", line 56, in getCompany
    company_description, company_website = get_company_info_from_linkedin(company_name)
                                           ~~~~~~~~~~~~~~~~~~~~~~~~~~~~~~^^^^^^^^^^^^^^
  File "/home/runner/hypercover/companyfinder.py", line 8, in get_company_info_from_linkedin
    api = Linkedin("tenil52929@pofmagic.com", "wz9yqrHzSzCMZvT")  # Use your LinkedIn credentials
  File "/home/runner/hypercover/.pythonlibs/lib/python3.13/site-packages/linkedin_api/linkedin.py", line 82, in __init__
    self.client.authenticate(username, password)
    ~~~~~~~~~~~~~~~~~~~~~~~~^^^^^^^^^^^^^^^^^^^^
  File "/home/runner/hypercover/.pythonlibs/lib/python3.13/site-packages/linkedin_api/client.py", line 101, in authenticate
    self._do_authentication_request(username, password)
    ~~~~~~~~~~~~~~~~~~~~~~~~~~~~~~~^^^^^^^^^^^^^^^^^^^^
  File "/home/runner/hypercover/.pythonlibs/lib/python3.13/site-packages/linkedin_api/client.py", line 163, in _do_authentication_request
    raise ChallengeException(data["login_result"])
linkedin_api.client.ChallengeException: CHALLENGE
172.31.196.69 - - [04/Jan/2025 23:19:48] "POST / HTTP/1.1" 500 -
INFO:werkzeug:172.31.196.69 - - [04/Jan/2025 23:19:48] "POST / HTTP/1.1" 500 -